Workbook

Sheet Summary
A1: Field-wise Validation Summary
A3: Field | B3: Precision | C3: Recall | D3: F1 Score | E3: Accuracy % (With Not Exist) | F3: Total Docs Tested | G3: No Of Docs With Data | H3: No Of Docs With Response
A4: Companies / company_name | B4: ='Field 1'!$L$3 | C4: ='Field 1'!$L$4 | D4: ='Field 1'!$L$5 | E4: ='Field 1'!$L$6 | F4: ='Field 1'!$L$7 | G4: ='Field 1'!$L$8 | H4: ='Field 1'!$L$9
A5: Companies / role_desc | B5: ='Field 2'!$L$3 | C5: ='Field 2'!$L$4 | D5: ='Field 2'!$L$5 | E5: ='Field 2'!$L$6 | F5: ='Field 2'!$L$7 | G5: ='Field 2'!$L$8 | H5: ='Field 2'!$L$9
A6: Lease_Comp_Details / act_1954_f | B6: ='Field 3'!$L$3 | C6: ='Field 3'!$L$4 | D6: ='Field 3'!$L$5 | E6: ='Field 3'!$L$6 | F6: ='Field 3'!$L$7 | G6: ='Field 3'!$L$8 | H6: ='Field 3'!$L$9
A7: Lease_Comp_Details / arrangement_end_action_status_reason_type_desc | B7: ='Field 4'!$L$3 | C7: ='Field 4'!$L$4 | D7: ='Field 4'!$L$5 | E7: ='Field 4'!$L$6 | F7: ='Field 4'!$L$7 | G7: ='Field 4'!$L$8 | H7: ='Field 4'!$L$9
A8: Lease_Comp_Details / arrangement_end_action_status_type_desc | B8: ='Field 5'!$L$3 | C8: ='Field 5'!$L$4 | D8: ='Field 5'!$L$5 | E8: ='Field 5'!$L$6 | F8: ='Field 5'!$L$7 | G8: ='Field 5'!$L$8 | H8: ='Field 5'!$L$9
A9: Lease_Comp_Details / arrangement_end_future_action_date | B9: ='Field 6'!$L$3 | C9: ='Field 6'!$L$4 | D9: ='Field 6'!$L$5 | E9: ='Field 6'!$L$6 | F9: ='Field 6'!$L$7 | G9: ='Field 6'!$L$8 | H9: ='Field 6'!$L$9
A10: Lease_Comp_Details / arrangement_end_future_action_type_desc | B10: ='Field 7'!$L$3 | C10: ='Field 7'!$L$4 | D10: ='Field 7'!$L$5 | E10: ='Field 7'!$L$6 | F10: ='Field 7'!$L$7 | G10: ='Field 7'!$L$8 | H10: ='Field 7'!$L$9
A11: Lease_Comp_Details / lease_arrangement_reason_type_desc | B11: ='Field 8'!$L$3 | C11: ='Field 8'!$L$4 | D11: ='Field 8'!$L$5 | E11: ='Field 8'!$L$6 | F11: ='Field 8'!$L$7 | G11: ='Field 8'!$L$8 | H11: ='Field 8'!$L$9
A12: Lease_Comp_Details / ref_lease_activity_type_desc | B12: ='Field 9'!$L$3 | C12: ='Field 9'!$L$4 | D12: ='Field 9'!$L$5 | E12: ='Field 9'!$L$6 | F12: ='Field 9'!$L$7 | G12: ='Field 9'!$L$8 | H12: ='Field 9'!$L$9
A13: Lease_Comp_Details / ref_lease_arrangement_type_desc | B13: ='Field 10'!$L$3 | C13: ='Field 10'!$L$4 | D13: ='Field 10'!$L$5 | E13: ='Field 10'!$L$6 | F13: ='Field 10'!$L$7 | G13: ='Field 10'!$L$8 | H13: ='Field 10'!$L$9
A14: Lease_Comp_Details / ref_total_leased_space_uom_desc | B14: ='Field 11'!$L$3 | C14: ='Field 11'!$L$4 | D14: ='Field 11'!$L$5 | E14: ='Field 11'!$L$6 | F14: ='Field 11'!$L$7 | G14: ='Field 11'!$L$8 | H14: ='Field 11'!$L$9
A15: Lease_Comp_Details / space_condition_type_desc | B15: ='Field 12'!$L$3 | C15: ='Field 12'!$L$4 | D15: ='Field 12'!$L$5 | E15: ='Field 12'!$L$6 | F15: ='Field 12'!$L$7 | G15: ='Field 12'!$L$8 | H15: ='Field 12'!$L$9
A16: Lease_Comp_Details / sublease_f | B16: ='Field 13'!$L$3 | C16: ='Field 13'!$L$4 | D16: ='Field 13'!$L$5 | E16: ='Field 13'!$L$6 | F16: ='Field 13'!$L$7 | G16: ='Field 13'!$L$8 | H16: ='Field 13'!$L$9
A17: Lease_Comp_Details / tenant_status_type_desc | B17: ='Field 14'!$L$3 | C17: ='Field 14'!$L$4 | D17: ='Field 14'!$L$5 | E17: ='Field 14'!$L$6 | F17: ='Field 14'!$L$7 | G17: ='Field 14'!$L$8 | H17: ='Field 14'!$L$9
A18: Lease_Comp_Details / total_leased_space | B18: ='Field 15'!$L$3 | C18: ='Field 15'!$L$4 | D18: ='Field 15'!$L$5 | E18: ='Field 15'!$L$6 | F18: ='Field 15'!$L$7 | G18: ='Field 15'!$L$8 | H18: ='Field 15'!$L$9
A19: Lease_Comp_Details / total_leased_space_estimated_f | B19: ='Field 16'!$L$3 | C19: ='Field 16'!$L$4 | D19: ='Field 16'!$L$5 | E19: ='Field 16'!$L$6 | F19: ='Field 16'!$L$7 | G19: ='Field 16'!$L$8 | H19: ='Field 16'!$L$9
A20: Property / property_name | B20: ='Field 17'!$L$3 | C20: ='Field 17'!$L$4 | D20: ='Field 17'!$L$5 | E20: ='Field 17'!$L$6 | F20: ='Field 17'!$L$7 | G20: ='Field 17'!$L$8 | H20: ='Field 17'!$L$9
A21: Terms / Arrangement_End_Date | B21: ='Field 18'!$L$3 | C21: ='Field 18'!$L$4 | D21: ='Field 18'!$L$5 | E21: ='Field 18'!$L$6 | F21: ='Field 18'!$L$7 | G21: ='Field 18'!$L$8 | H21: ='Field 18'!$L$9
A22: Terms / Arrangement_Signed_Date | B22: ='Field 19'!$L$3 | C22: ='Field 19'!$L$4 | D22: ='Field 19'!$L$5 | E22: ='Field 19'!$L$6 | F22: ='Field 19'!$L$7 | G22: ='Field 19'!$L$8 | H22: ='Field 19'!$L$9
A23: Terms / Arrangement_Start_Date | B23: ='Field 20'!$L$3 | C23: ='Field 20'!$L$4 | D23: ='Field 20'!$L$5 | E23: ='Field 20'!$L$6 | F23: ='Field 20'!$L$7 | G23: ='Field 20'!$L$8 | H23: ='Field 20'!$L$9
A24: Terms / Asking_Rent_Monthly | B24: ='Field 21'!$L$3 | C24: ='Field 21'!$L$4 | D24: ='Field 21'!$L$5 | E24: ='Field 21'!$L$6 | F24: ='Field 21'!$L$7 | G24: ='Field 21'!$L$8 | H24: ='Field 21'!$L$9
A25: Terms / Asking_Rent_Yearly | B25: ='Field 22'!$L$3 | C25: ='Field 22'!$L$4 | D25: ='Field 22'!$L$5 | E25: ='Field 22'!$L$6 | F25: ='Field 22'!$L$7 | G25: ='Field 22'!$L$8 | H25: ='Field 22'!$L$9
A26: Terms / Cost_per_Reserved_Parking_Space | B26: ='Field 23'!$L$3 | C26: ='Field 23'!$L$4 | D26: ='Field 23'!$L$5 | E26: ='Field 23'!$L$6 | F26: ='Field 23'!$L$7 | G26: ='Field 23'!$L$8 | H26: ='Field 23'!$L$9
A27: Terms / Effective_Rent_Monthly | B27: ='Field 24'!$L$3 | C27: ='Field 24'!$L$4 | D27: ='Field 24'!$L$5 | E27: ='Field 24'!$L$6 | F27: ='Field 24'!$L$7 | G27: ='Field 24'!$L$8 | H27: ='Field 24'!$L$9
A28: Terms / Effective_Rent_Yearly | B28: ='Field 25'!$L$3 | C28: ='Field 25'!$L$4 | D28: ='Field 25'!$L$5 | E28: ='Field 25'!$L$6 | F28: ='Field 25'!$L$7 | G28: ='Field 25'!$L$8 | H28: ='Field 25'!$L$9
A29: Terms / Lease_Term | B29: ='Field 26'!$L$3 | C29: ='Field 26'!$L$4 | D29: ='Field 26'!$L$5 | E29: ='Field 26'!$L$6 | F29: ='Field 26'!$L$7 | G29: ='Field 26'!$L$8 | H29: ='Field 26'!$L$9
A30: Terms / Number_Of_Month_Free_Rent | B30: ='Field 27'!$L$3 | C30: ='Field 27'!$L$4 | D30: ='Field 27'!$L$5 | E30: ='Field 27'!$L$6 | F30: ='Field 27'!$L$7 | G30: ='Field 27'!$L$8 | H30: ='Field 27'!$L$9
A31: Terms / Occupancy_Date | B31: ='Field 28'!$L$3 | C31: ='Field 28'!$L$4 | D31: ='Field 28'!$L$5 | E31: ='Field 28'!$L$6 | F31: ='Field 28'!$L$7 | G31: ='Field 28'!$L$8 | H31: ='Field 28'!$L$9
A32: Terms / Option_Notes | B32: ='Field 29'!$L$3 | C32: ='Field 29'!$L$4 | D32: ='Field 29'!$L$5 | E32: ='Field 29'!$L$6 | F32: ='Field 29'!$L$7 | G32: ='Field 29'!$L$8 | H32: ='Field 29'!$L$9
A33: Terms / Ref_asking_rent_monthly_uom_desc | B33: ='Field 30'!$L$3 | C33: ='Field 30'!$L$4 | D33: ='Field 30'!$L$5 | E33: ='Field 30'!$L$6 | F33: ='Field 30'!$L$7 | G33: ='Field 30'!$L$8 | H33: ='Field 30'!$L$9
A34: Terms / Ref_asking_rent_yearly_uom_desc | B34: ='Field 31'!$L$3 | C34: ='Field 31'!$L$4 | D34: ='Field 31'!$L$5 | E34: ='Field 31'!$L$6 | F34: ='Field 31'!$L$7 | G34: ='Field 31'!$L$8 | H34: ='Field 31'!$L$9
A35: Terms / Ref_cost_per_reserved_parking_space_uom_desc | B35: ='Field 32'!$L$3 | C35: ='Field 32'!$L$4 | D35: ='Field 32'!$L$5 | E35: ='Field 32'!$L$6 | F35: ='Field 32'!$L$7 | G35: ='Field 32'!$L$8 | H35: ='Field 32'!$L$9
A36: Terms / Ref_effective_rent_monthly_uom_desc | B36: ='Field 33'!$L$3 | C36: ='Field 33'!$L$4 | D36: ='Field 33'!$L$5 | E36: ='Field 33'!$L$6 | F36: ='Field 33'!$L$7 | G36: ='Field 33'!$L$8 | H36: ='Field 33'!$L$9
A37: Terms / Ref_effective_rent_yearly_uom_desc | B37: ='Field 34'!$L$3 | C37: ='Field 34'!$L$4 | D37: ='Field 34'!$L$5 | E37: ='Field 34'!$L$6 | F37: ='Field 34'!$L$7 | G37: ='Field 34'!$L$8 | H37: ='Field 34'!$L$9
A38: Terms / Ref_lease_term_uom_desc | B38: ='Field 35'!$L$3 | C38: ='Field 35'!$L$4 | D38: ='Field 35'!$L$5 | E38: ='Field 35'!$L$6 | F38: ='Field 35'!$L$7 | G38: ='Field 35'!$L$8 | H38: ='Field 35'!$L$9
A39: Terms / Ref_service_charge_per_area_value_price_uom_desc | B39: ='Field 36'!$L$3 | C39: ='Field 36'!$L$4 | D39: ='Field 36'!$L$5 | E39: ='Field 36'!$L$6 | F39: ='Field 36'!$L$7 | G39: ='Field 36'!$L$8 | H39: ='Field 36'!$L$9
A40: Terms / Ref_tenant_improvement_allowance_uom_desc | B40: ='Field 37'!$L$3 | C40: ='Field 37'!$L$4 | D40: ='Field 37'!$L$5 | E40: ='Field 37'!$L$6 | F40: ='Field 37'!$L$7 | G40: ='Field 37'!$L$8 | H40: ='Field 37'!$L$9
A41: Terms / Reserved_Parking_Spaces | B41: ='Field 38'!$L$3 | C41: ='Field 38'!$L$4 | D41: ='Field 38'!$L$5 | E41: ='Field 38'!$L$6 | F41: ='Field 38'!$L$7 | G41: ='Field 38'!$L$8 | H41: ='Field 38'!$L$9
...

Sheet Page Summary
A1: Field-wise Page Number Summary
A3: Field | B3: Precision | C3: Recall | D3: F1 Score | E3: Accuracy % (With Not Exist) | F3: Total Docs Tested | G3: No Of Docs With Manual Pg | H3: No Of Docs With Response Pg
A4: Companies / company_name | B4: ='Field 1'!$O$3 | C4: ='Field 1'!$O$4 | D4: ='Field 1'!$O$5 | E4: ='Field 1'!$O$6 | F4: ='Field 1'!$O$7 | G4: ='Field 1'!$O$8 | H4: ='Field 1'!$O$9
A5: Companies / role_desc | B5: ='Field 2'!$O$3 | C5: ='Field 2'!$O$4 | D5: ='Field 2'!$O$5 | E5: ='Field 2'!$O$6 | F5: ='Field 2'!$O$7 | G5: ='Field 2'!$O$8 | H5: ='Field 2'!$O$9
A6: Lease_Comp_Details / act_1954_f | B6: ='Field 3'!$O$3 | C6: ='Field 3'!$O$4 | D6: ='Field 3'!$O$5 | E6: ='Field 3'!$O$6 | F6: ='Field 3'!$O$7 | G6: ='Field 3'!$O$8 | H6: ='Field 3'!$O$9
A7: Lease_Comp_Details / arrangement_end_action_status_reason_type_desc | B7: ='Field 4'!$O$3 | C7: ='Field 4'!$O$4 | D7: ='Field 4'!$O$5 | E7: ='Field 4'!$O$6 | F7: ='Field 4'!$O$7 | G7: ='Field 4'!$O$8 | H7: ='Field 4'!$O$9
A8: Lease_Comp_Details / arrangement_end_action_status_type_desc | B8: ='Field 5'!$O$3 | C8: ='Field 5'!$O$4 | D8: ='Field 5'!$O$5 | E8: ='Field 5'!$O$6 | F8: ='Field 5'!$O$7 | G8: ='Field 5'!$O$8 | H8: ='Field 5'!$O$9
A9: Lease_Comp_Details / arrangement_end_future_action_date | B9: ='Field 6'!$O$3 | C9: ='Field 6'!$O$4 | D9: ='Field 6'!$O$5 | E9: ='Field 6'!$O$6 | F9: ='Field 6'!$O$7 | G9: ='Field 6'!$O$8 | H9: ='Field 6'!$O$9
A10: Lease_Comp_Details / arrangement_end_future_action_type_desc | B10: ='Field 7'!$O$3 | C10: ='Field 7'!$O$4 | D10: ='Field 7'!$O$5 | E10: ='Field 7'!$O$6 | F10: ='Field 7'!$O$7 | G10: ='Field 7'!$O$8 | H10: ='Field 7'!$O$9
A11: Lease_Comp_Details / lease_arrangement_reason_type_desc | B11: ='Field 8'!$O$3 | C11: ='Field 8'!$O$4 | D11: ='Field 8'!$O$5 | E11: ='Field 8'!$O$6 | F11: ='Field 8'!$O$7 | G11: ='Field 8'!$O$8 | H11: ='Field 8'!$O$9
A12: Lease_Comp_Details / ref_lease_activity_type_desc | B12: ='Field 9'!$O$3 | C12: ='Field 9'!$O$4 | D12: ='Field 9'!$O$5 | E12: ='Field 9'!$O$6 | F12: ='Field 9'!$O$7 | G12: ='Field 9'!$O$8 | H12: ='Field 9'!$O$9
A13: Lease_Comp_Details / ref_lease_arrangement_type_desc | B13: ='Field 10'!$O$3 | C13: ='Field 10'!$O$4 | D13: ='Field 10'!$O$5 | E13: ='Field 10'!$O$6 | F13: ='Field 10'!$O$7 | G13: ='Field 10'!$O$8 | H13: ='Field 10'!$O$9
A14: Lease_Comp_Details / ref_total_leased_space_uom_desc | B14: ='Field 11'!$O$3 | C14: ='Field 11'!$O$4 | D14: ='Field 11'!$O$5 | E14: ='Field 11'!$O$6 | F14: ='Field 11'!$O$7 | G14: ='Field 11'!$O$8 | H14: ='Field 11'!$O$9
A15: Lease_Comp_Details / space_condition_type_desc | B15: ='Field 12'!$O$3 | C15: ='Field 12'!$O$4 | D15: ='Field 12'!$O$5 | E15: ='Field 12'!$O$6 | F15: ='Field 12'!$O$7 | G15: ='Field 12'!$O$8 | H15: ='Field 12'!$O$9
A16: Lease_Comp_Details / sublease_f | B16: ='Field 13'!$O$3 | C16: ='Field 13'!$O$4 | D16: ='Field 13'!$O$5 | E16: ='Field 13'!$O$6 | F16: ='Field 13'!$O$7 | G16: ='Field 13'!$O$8 | H16: ='Field 13'!$O$9
A17: Lease_Comp_Details / tenant_status_type_desc | B17: ='Field 14'!$O$3 | C17: ='Field 14'!$O$4 | D17: ='Field 14'!$O$5 | E17: ='Field 14'!$O$6 | F17: ='Field 14'!$O$7 | G17: ='Field 14'!$O$8 | H17: ='Field 14'!$O$9
A18: Lease_Comp_Details / total_leased_space | B18: ='Field 15'!$O$3 | C18: ='Field 15'!$O$4 | D18: ='Field 15'!$O$5 | E18: ='Field 15'!$O$6 | F18: ='Field 15'!$O$7 | G18: ='Field 15'!$O$8 | H18: ='Field 15'!$O$9
A19: Lease_Comp_Details / total_leased_space_estimated_f | B19: ='Field 16'!$O$3 | C19: ='Field 16'!$O$4 | D19: ='Field 16'!$O$5 | E19: ='Field 16'!$O$6 | F19: ='Field 16'!$O$7 | G19: ='Field 16'!$O$8 | H19: ='Field 16'!$O$9
A20: Property / property_name | B20: ='Field 17'!$O$3 | C20: ='Field 17'!$O$4 | D20: ='Field 17'!$O$5 | E20: ='Field 17'!$O$6 | F20: ='Field 17'!$O$7 | G20: ='Field 17'!$O$8 | H20: ='Field 17'!$O$9
A21: Terms / Arrangement_End_Date | B21: ='Field 18'!$O$3 | C21: ='Field 18'!$O$4 | D21: ='Field 18'!$O$5 | E21: ='Field 18'!$O$6 | F21: ='Field 18'!$O$7 | G21: ='Field 18'!$O$8 | H21: ='Field 18'!$O$9
A22: Terms / Arrangement_Signed_Date | B22: ='Field 19'!$O$3 | C22: ='Field 19'!$O$4 | D22: ='Field 19'!$O$5 | E22: ='Field 19'!$O$6 | F22: ='Field 19'!$O$7 | G22: ='Field 19'!$O$8 | H22: ='Field 19'!$O$9
A23: Terms / Arrangement_Start_Date | B23: ='Field 20'!$O$3 | C23: ='Field 20'!$O$4 | D23: ='Field 20'!$O$5 | E23: ='Field 20'!$O$6 | F23: ='Field 20'!$O$7 | G23: ='Field 20'!$O$8 | H23: ='Field 20'!$O$9
A24: Terms / Asking_Rent_Monthly | B24: ='Field 21'!$O$3 | C24: ='Field 21'!$O$4 | D24: ='Field 21'!$O$5 | E24: ='Field 21'!$O$6 | F24: ='Field 21'!$O$7 | G24: ='Field 21'!$O$8 | H24: ='Field 21'!$O$9
A25: Terms / Asking_Rent_Yearly | B25: ='Field 22'!$O$3 | C25: ='Field 22'!$O$4 | D25: ='Field 22'!$O$5 | E25: ='Field 22'!$O$6 | F25: ='Field 22'!$O$7 | G25: ='Field 22'!$O$8 | H25: ='Field 22'!$O$9
A26: Terms / Cost_per_Reserved_Parking_Space | B26: ='Field 23'!$O$3 | C26: ='Field 23'!$O$4 | D26: ='Field 23'!$O$5 | E26: ='Field 23'!$O$6 | F26: ='Field 23'!$O$7 | G26: ='Field 23'!$O$8 | H26: ='Field 23'!$O$9
A27: Terms / Effective_Rent_Monthly | B27: ='Field 24'!$O$3 | C27: ='Field 24'!$O$4 | D27: ='Field 24'!$O$5 | E27: ='Field 24'!$O$6 | F27: ='Field 24'!$O$7 | G27: ='Field 24'!$O$8 | H27: ='Field 24'!$O$9
A28: Terms / Effective_Rent_Yearly | B28: ='Field 25'!$O$3 | C28: ='Field 25'!$O$4 | D28: ='Field 25'!$O$5 | E28: ='Field 25'!$O$6 | F28: ='Field 25'!$O$7 | G28: ='Field 25'!$O$8 | H28: ='Field 25'!$O$9
A29: Terms / Lease_Term | B29: ='Field 26'!$O$3 | C29: ='Field 26'!$O$4 | D29: ='Field 26'!$O$5 | E29: ='Field 26'!$O$6 | F29: ='Field 26'!$O$7 | G29: ='Field 26'!$O$8 | H29: ='Field 26'!$O$9
A30: Terms / Number_Of_Month_Free_Rent | B30: ='Field 27'!$O$3 | C30: ='Field 27'!$O$4 | D30: ='Field 27'!$O$5 | E30: ='Field 27'!$O$6 | F30: ='Field 27'!$O$7 | G30: ='Field 27'!$O$8 | H30: ='Field 27'!$O$9
A31: Terms / Occupancy_Date | B31: ='Field 28'!$O$3 | C31: ='Field 28'!$O$4 | D31: ='Field 28'!$O$5 | E31: ='Field 28'!$O$6 | F31: ='Field 28'!$O$7 | G31: ='Field 28'!$O$8 | H31: ='Field 28'!$O$9
A32: Terms / Option_Notes | B32: ='Field 29'!$O$3 | C32: ='Field 29'!$O$4 | D32: ='Field 29'!$O$5 | E32: ='Field 29'!$O$6 | F32: ='Field 29'!$O$7 | G32: ='Field 29'!$O$8 | H32: ='Field 29'!$O$9
A33: Terms / Ref_asking_rent_monthly_uom_desc | B33: ='Field 30'!$O$3 | C33: ='Field 30'!$O$4 | D33: ='Field 30'!$O$5 | E33: ='Field 30'!$O$6 | F33: ='Field 30'!$O$7 | G33: ='Field 30'!$O$8 | H33: ='Field 30'!$O$9
A34: Terms / Ref_asking_rent_yearly_uom_desc | B34: ='Field 31'!$O$3 | C34: ='Field 31'!$O$4 | D34: ='Field 31'!$O$5 | E34: ='Field 31'!$O$6 | F34: ='Field 31'!$O$7 | G34: ='Field 31'!$O$8 | H34: ='Field 31'!$O$9
A35: Terms / Ref_cost_per_reserved_parking_space_uom_desc | B35: ='Field 32'!$O$3 | C35: ='Field 32'!$O$4 | D35: ='Field 32'!$O$5 | E35: ='Field 32'!$O$6 | F35: ='Field 32'!$O$7 | G35: ='Field 32'!$O$8 | H35: ='Field 32'!$O$9
A36: Terms / Ref_effective_rent_monthly_uom_desc | B36: ='Field 33'!$O$3 | C36: ='Field 33'!$O$4 | D36: ='Field 33'!$O$5 | E36: ='Field 33'!$O$6 | F36: ='Field 33'!$O$7 | G36: ='Field 33'!$O$8 | H36: ='Field 33'!$O$9
A37: Terms / Ref_effective_rent_yearly_uom_desc | B37: ='Field 34'!$O$3 | C37: ='Field 34'!$O$4 | D37: ='Field 34'!$O$5 | E37: ='Field 34'!$O$6 | F37: ='Field 34'!$O$7 | G37: ='Field 34'!$O$8 | H37: ='Field 34'!$O$9
A38: Terms / Ref_lease_term_uom_desc | B38: ='Field 35'!$O$3 | C38: ='Field 35'!$O$4 | D38: ='Field 35'!$O$5 | E38: ='Field 35'!$O$6 | F38: ='Field 35'!$O$7 | G38: ='Field 35'!$O$8 | H38: ='Field 35'!$O$9
A39: Terms / Ref_service_charge_per_area_value_price_uom_desc | B39: ='Field 36'!$O$3 | C39: ='Field 36'!$O$4 | D39: ='Field 36'!$O$5 | E39: ='Field 36'!$O$6 | F39: ='Field 36'!$O$7 | G39: ='Field 36'!$O$8 | H39: ='Field 36'!$O$9
A40: Terms / Ref_tenant_improvement_allowance_uom_desc | B40: ='Field 37'!$O$3 | C40: ='Field 37'!$O$4 | D40: ='Field 37'!$O$5 | E40: ='Field 37'!$O$6 | F40: ='Field 37'!$O$7 | G40: ='Field 37'!$O$8 | H40: ='Field 37'!$O$9
A41: Terms / Reserved_Parking_Spaces | B41: ='Field 38'!$O$3 | C41: ='Field 38'!$O$4 | D41: ='Field 38'!$O$5 | E41: ='Field 38'!$O$6 | F41: ='Field 38'!$O$7 | G41: ='Field 38'!$O$8 | H41: ='Field 38'!$O$9
...

Sheet Token Summary
A1: Token Consumption Summary
A3: Metric | B3: Value
A4: Run ID | B4: abstract-method-2-20261007-152636
A5: Flow | B5: abstract
A6: Total Documents | B6: 35
A7: Documents With Token Data | B7: 35
A8: Total Unique Fields | B8: 64
A9: Total LLM Tokens | B9: 52142171
A10: Total Embedding Tokens | B10: 6836420
A11: Total Tokens | B11: 58978591
A12: Total API Calls | B12: 2905
A13: Total Cost (USD) | B13: 41.674336
A14: Avg Cost / Document (USD) | B14: 1.1906953
A15: Avg Tokens / Document | B15: 1685103
A16: Unpriced Models | B16: None

Sheet Token by Model
A1: Token Consumption by Model
A3: Model | B3: Type | C3: Calls | D3: Prompt Tokens | E3: Cached Tokens | F3: Completion Tokens | G3: Thought Tokens | H3: Embedding Tokens | I3: Total Tokens | J3: Prompt USD/M | K3: Cached USD/M | L3: Completion USD/M | M3: Thoughts USD/M | N3: Embedding USD/M | O3: Cost (USD)
A4: gemini-2.5-flash | B4: LLM | C4: 1190 | D4: 22229725 | E4: 1931128 | F4: 800801 | G4: 0 | H4: 0 | I4: 23030526 | J4: 0.3 | K4: 0.03 | L4: 2.5 | M4: 2.5 | N4: - | O4: 8.1495154
A5: gpt-4.1 | B5: LLM | C5: 1715 | D5: 28903603 | E5: 17890304 | F5: 208042 | G5: 0 | H5: 0 | I5: 29111645 | J5: 2 | K5: 0.5 | L5: 8 | M5: 0 | N5: - | O5: 32.636086
A6: text-embedding-3-large | B6: Embedding | C6: 0 | D6: 0 | E6: 0 | F6: 0 | G6: 0 | H6: 6836420 | I6: 6836420 | J6: - | K6: - | L6: - | M6: - | N6: 0.13 | O6: 0.8887346
A7: TOTAL | C7: 2905 | D7: 51133328 | E7: 19821432 | F7: 1008843 | G7: 0 | H7: 6836420 | I7: 58978591 | O7: 41.674336

Sheet Token by Document
A1: Token Consumption by Document
A3: Document | B3: Fields Extracted | C3: API Calls | D3: LLM Tokens | E3: Embedding Tokens | F3: Total Tokens | G3: Cost (USD)
A4: 20181204 Huurovereenkomst (GETEKEND).PDF | B4: 49 | C4: 83 | D4: 834470 | E4: 52240 | F4: 886710 | G4: 0.73602885
A5: 2024.10.30_Office Rental Agreement Labs_Gruyter Fabriek.pdf | B5: 50 | C5: 83 | D5: 1547491 | E5: 172100 | F5: 1719591 | G5: 1.150876
A6: 20240606_HOK AKD - EDGE Eindhoven execution version.pdf | B6: 61 | C6: 83 | D6: 1156274 | E6: 81945 | F6: 1238219 | G6: 1.0404708
A7: 20250117_HOK Duke Strategies - Hambaken A.05.09 DEF FULLY SIGNED.pdf | B7: 59 | C7: 83 | D7: 755829 | E7: 43825 | F7: 799654 | G7: 0.68759779
A8: 20251216 Lease agreement ASPEN - signed.pdf | B8: 47 | C8: 83 | D8: 2318729 | E8: 809225 | F8: 3127954 | G8: 1.6603155
A9: 20260220 Huurovereenkomst signed 20-02-2026.pdf | B9: 61 | C9: 83 | D9: 1419257 | E9: 176110 | F9: 1595367 | G9: 1.1557177
A10: 20260629 HOK ADHDcentraal BV (1).pdf | B10: 60 | C10: 83 | D10: 1658829 | E10: 205635 | F10: 1864464 | G10: 1.3063745
A11: 20260807_Happy_Village_B.V._Lease_Maasstadweg_tekenversie_incl._bijlagen en-GB.pdf | B11: 52 | C11: 83 | D11: 1888487 | E11: 224065 | F11: 2112552 | G11: 1.5257897
A12: 20260810 HOK ClustR BV.pdf | B12: 57 | C12: 83 | D12: 1518601 | E12: 205610 | F12: 1724211 | G12: 1.2413751
A13: 20270801 - Getekende Allonge II Advario BV.pdf | B13: 56 | C13: 83 | D13: 932565 | E13: 73810 | F13: 1006375 | G13: 0.84872898
A14: 240119 HOVK Spoorlaan 446-448 Tilburg signed.pdf | B14: 54 | C14: 83 | D14: 1401388 | E14: 154760 | F14: 1556148 | G14: 1.078759
A15: 27001 Rijksvastgoedbedrijf Huurovereenkomst - __27-01-2026_9-07-56.pdf | B15: 60 | C15: 83 | D15: 1396866 | E15: 122050 | F15: 1518916 | G15: 1.2680421
... A39: TOTAL | B39: 64 | C39: 2905 | D39: 52142171 | E39: 6836420 | F39: 58978591 | G39: 41.674336

Sheet Field 1
A1: Doc Name | B1: Manual Data | C1: Response Data | D1: Result | E1: Manual Pg | F1: Response Pg No | G1: Pg Result | H1: Confidence | K1: SUMMARY SHEET | N1: PAGE SUMMARY SHEET
A2: 20181204 Huurovereenkomst (GETEKEND).PDF | C2: Herbax Novum B.V. | H2: 0.95 | K2: Metrics | L2: Percentage | N2: Metrics | O2: Percentage
A3: 2024.10.30_Office Rental Agreement Labs_Gruyter Fabriek.pdf | C3: N.V. Bossche Investerings-Maatschappij h.o.d.n. De Gruyter Fabriek | H3: 0.95 | K3: Precision | L3: =IFERROR(COUNTIFS(D2:D36,"TP")/(COUNTIFS(D2:D36,"TP")+COUNTIFS(D2:D36,"FP")),0) | N3: Precision | O3: =IFERROR(COUNTIFS(G2:G36,"TP")/(COUNTIFS(G2:G36,"TP")+COUNTIFS(G2:G36,"FP")),0)
A4: 20240606_HOK AKD - EDGE Eindhoven execution version.pdf | C4: EDGE TECHNOLOGIES DEVELOPMENT 1 B.V. | H4: 0.95 | K4: Recall | L4: =IFERROR(COUNTIFS(D2:D36,"TP")/(COUNTIFS(D2:D36,"TP")+COUNTIFS(D2:D36,"FN")),0) | N4: Recall | O4: =IFERROR(COUNTIFS(G2:G36,"TP")/(COUNTIFS(G2:G36,"TP")+COUNTIFS(G2:G36,"FN")),0)
A5: 20250117_HOK Duke Strategies - Hambaken A.05.09 DEF FULLY SIGNED.pdf | C5: Campus Hambaken B.V. | H5: 0.95 | K5: F1 Score | L5: =IFERROR(2*COUNTIFS(D2:D36,"TP")/(2*COUNTIFS(D2:D36,"TP")+COUNTIFS(D2:D36,"FP")+COUNTIFS(D2:D36,"FN")),0) | N5: F1 Score | O5: =IFERROR(2*COUNTIFS(G2:G36,"TP")/(2*COUNTIFS(G2:G36,"TP")+COUNTIFS(G2:G36,"FP")+COUNTIFS(G2:G36,"FN")),0)
A6: 20251216 Lease agreement ASPEN - signed.pdf | C6: Pivot Park Vastgoed B.V. | H6: 0.95 | K6: Accuracy % (With Not Exist) | L6: =IFERROR((COUNTIF(D2:D36,"TP")+COUNTIF(D2:D36,"TN"))/SUM(COUNTIF(D2:D36,{"TP","TN","FP","FN"})),0) | N6: Accuracy % (With Not Exist) | O6: =IFERROR((COUNTIF(G2:G36,"TP")+COUNTIF(G2:G36,"TN"))/SUM(COUNTIF(G2:G36,{"TP","TN","FP","FN"})),0)
A7: 20260220 Huurovereenkomst signed 20-02-2026.pdf | C7: Bond Park C.V. | H7: 0.95 | K7: Total Docs Tested | L7: =COUNTA(A2:A36) | N7: Total Docs Tested | O7: =COUNTA(A2:A36)
A8: 20260629 HOK ADHDcentraal BV (1).pdf | C8: ADHDcentraal B.V. | H8: 0.95 | K8: No Of Docs With Data | L8: =COUNTIFS(B2:B36,"<>",B2:B36,"<>N/A",B2:B36,"<>Not Present In the Document",B2:B36,"<>Not Found",B2:B36,"<>i dont know",B2:B36,"<>i don't know") | N8: No Of Docs With Manual Pg | O8: =COUNTIFS(E2:E36,"<>",E2:E36,"<>N/A",E2:E36,"<>Not Present In the Document",E2:E36,"<>Not Found",E2:E36,"<>i dont know",E2:E36,"<>i don't know")
A9: 20260807_Happy_Village_B.V._Lease_Maasstadweg_tekenversie_incl._bijlagen en-GB.pdf | C9: Nightingale Rotterdam I B.V. | H9: 0.95 | K9: No Of Docs With Response | L9: =COUNTIFS(C2:C36,"<>") | N9: No Of Docs With Response Pg | O9: =COUNTIFS(F2:F36,"<>")
A10: 20260810 HOK ClustR BV.pdf | C10: Campus Hambaken B.V. | H10: 0.95 | K10: Highlighted rows = file(s) not in the annotation sheet; excluded from all metrics above.
A11: 20270801 - Getekende Allonge II Advario BV.pdf | C11: Stichting Bouwinvest Dutch Institutional Office Fund | H11: 0.95 | K11: Validation Rules Example
A12: 240119 HOVK Spoorlaan 446-448 Tilburg signed.pdf | C12: DAF TEI Manager B.V. | H12: 0.95 | K12: Manual Data | L12: Response Data | M12: Result
A13: 27001 Rijksvastgoedbedrijf Huurovereenkomst - __27-01-2026_9-07-56.pdf | C13: NSI Kantoren BV | H13: 0.95 | K13: 100 | L13: 100 | M13: TP
A14: CBRE_AT_Services_ENG_-_RITUALS_CBRE signed.pdf | C14: Rituals Cosmetics Enterprise B.V. | H14: 0.95 | L14: 100 | M14: FP
A15: CBRE_Engagement_Letter_Alnylam_20260525_CLEAN_Version_signed all.pdf | C15: Alnylam Italy S.r.l. | H15: 0.95 | K15: 100 | L15: 200 | M15: FP
A16: COMPL DEF Huurovereenkomst - Skybox - Pepperl+Fuchs - 20260204.pdf | C16: ComfortZone Vastgoed III B.V. | H16: 0.96958763 | K16: 100 | M16: FN
A17: COMPL Huurovereenkomst - Stichting CCE - Kantoorgebouw Metzpoint I Dr. Holtroplaan - Fully Signed.pdf | C17: Foxhouse Invest B.V. | H17: 0.95 | M17: TN
A18: COMPL Regel Partners - HOVK - Luchthavenweg 81 - 20260728.pdf | C18: Stichting Juridisch Eigenaar Benkey Vastgoed | H18: 0.95
A19: COMPL_-_Onderhuurovereenkomst_Zelfstroom_B.V._-_50five_B.V._-_kantoorgebouw_Riva_-_05032026.pdf | C19: Zelfstroom B.V. | H19: 0.95 | K19: Field: | L19: Companies / company_name
A20: Den Bosch, Ruwekampweg 4, HOVK getekend.pdf | C20: S.F.M. Duijndam | H20: 0.96476684
A21: FULLY SIGNED - COMPL Huurovereenkomst - Heijmans - Hugo de Grootlaan 23 's-Hertogenbosch V2 30-9-2025.pdf | C21: 2Contact Groep B.V. | H21: 0.95
A22: FULLY SIGNED - DEF_COMPL_Huurovereenkomst_Robo_Charge_-_Campus_Offices_-_20260220.pdf | C22: Campus Hambaken B.V. | H22: 0.95
A23: FULLY SIGNED - Onderhuurovereenkomst Aartshertogenlaan 223, `s-Hertogenbosch - Koning Willem I College B.V. 2606202.pdf | C23: Luzac Opleidingen B.V. | H23: 0.95
A24: FULLY SIGNED COMPL_DEF_Huurovereenkomst_Bond_Bergschot_Breda.pdf | C24: Bergschot Breda B.V. | H24: 0.95
A25: FullySigned_Allonge_II_Virtual_Vaults_Nederland.pdf | C25: Newomij International V B.V. | H25: 0.95
A26: FullySigned_Lease_Agreement_Neste_EDGE_Coolsingel.pdf | C26: EDGE Development 8 B.V. | H26: 0.95
A27: HOK Waalhaven Group (signed).pdf | C27: M7 EREIP V Lux Dutch Holdco S.a r.l. | H27: 0.95
A28: Hovk Avans (3e+4e+5e verd.) 20140425.pdf | C28: TMW Pramerica Property Investments GmbH | H28: 0.96958763
A29: HOVK Power4People 2025.pdf | C29: OFY Breda B.V. | H29: 0.95
A30: Huurovereenkomst (Semmie Group B.V.) - Wilhelminasingel 19, Breda.pdf | C30: Het Malieveld B.V. | H30: 0.95
A31: Huurovereenkomst - proces-verbaal van oplevering - sleuteloverdracht - Kennedyplein 101 - getekend.pdf | C31: Gemeente Eindhoven | H31: 0.95
... A36: MWO CBRE SPA (ITALY) CBRE_090724.pdf | C36: Amazon EU S.a r.l. | H36: 0.96958763

Sheet Field 2
A1: Doc Name | B1: Manual Data | C1: Response Data | D1: Result | E1: Manual Pg | F1: Response Pg No | G1: Pg Result | H1: Confidence | K1: SUMMARY SHEET | N1: PAGE SUMMARY SHEET
A2: 20181204 Huurovereenkomst (GETEKEND).PDF | C2: LEGAL OWNER | H2: 0.95 | K2: Metrics | L2: Percentage | N2: Metrics | O2: Percentage
A3: 2024.10.30_Office Rental Agreement Labs_Gruyter Fabriek.pdf | C3: LEGAL OWNER | H3: 0.95 | K3: Precision | L3: =IFERROR(COUNTIFS(D2:D36,"TP")/(COUNTIFS(D2:D36,"TP")+COUNTIFS(D2:D36,"FP")),0) | N3: Precision | O3: =IFERROR(COUNTIFS(G2:G36,"TP")/(COUNTIFS(G2:G36,"TP")+COUNTIFS(G2:G36,"FP")),0)
A4: 20240606_HOK AKD - EDGE Eindhoven execution version.pdf | C4: LEGAL OWNER | H4: 0.95 | K4: Recall | L4: =IFERROR(COUNTIFS(D2:D36,"TP")/(COUNTIFS(D2:D36,"TP")+COUNTIFS(D2:D36,"FN")),0) | N4: Recall | O4: =IFERROR(COUNTIFS(G2:G36,"TP")/(COUNTIFS(G2:G36,"TP")+COUNTIFS(G2:G36,"FN")),0)
A5: 20250117_HOK Duke Strategies - Hambaken A.05.09 DEF FULLY SIGNED.pdf | C5: LEGAL OWNER | H5: 0.95 | K5: F1 Score | L5: =IFERROR(2*COUNTIFS(D2:D36,"TP")/(2*COUNTIFS(D2:D36,"TP")+COUNTIFS(D2:D36,"FP")+COUNTIFS(D2:D36,"FN")),0) | N5: F1 Score | O5: =IFERROR(2*COUNTIFS(G2:G36,"TP")/(2*COUNTIFS(G2:G36,"TP")+COUNTIFS(G2:G36,"FP")+COUNTIFS(G2:G36,"FN")),0)
A6: 20251216 Lease agreement ASPEN - signed.pdf | C6: LEGAL OWNER | H6: 0.95 | K6: Accuracy % (With Not Exist) | L6: =IFERROR((COUNTIF(D2:D36,"TP")+COUNTIF(D2:D36,"TN"))/SUM(COUNTIF(D2:D36,{"TP","TN","FP","FN"})),0) | N6: Accuracy % (With Not Exist) | O6: =IFERROR((COUNTIF(G2:G36,"TP")+COUNTIF(G2:G36,"TN"))/SUM(COUNTIF(G2:G36,{"TP","TN","FP","FN"})),0)
A7: 20260220 Huurovereenkomst signed 20-02-2026.pdf | C7: LEGAL OWNER | H7: 0.95 | K7: Total Docs Tested | L7: =COUNTA(A2:A36) | N7: Total Docs Tested | O7: =COUNTA(A2:A36)
A8: 20260629 HOK ADHDcentraal BV (1).pdf | C8: TENANT | H8: 0.95 | K8: No Of Docs With Data | L8: =COUNTIFS(B2:B36,"<>",B2:B36,"<>N/A",B2:B36,"<>Not Present In the Document",B2:B36,"<>Not Found",B2:B36,"<>i dont know",B2:B36,"<>i don't know") | N8: No Of Docs With Manual Pg | O8: =COUNTIFS(E2:E36,"<>",E2:E36,"<>N/A",E2:E36,"<>Not Present In the Document",E2:E36,"<>Not Found",E2:E36,"<>i dont know",E2:E36,"<>i don't know")
A9: 20260807_Happy_Village_B.V._Lease_Maasstadweg_tekenversie_incl._bijlagen en-GB.pdf | C9: LEGAL OWNER | H9: 0.95 | K9: No Of Docs With Response | L9: =COUNTIFS(C2:C36,"<>") | N9: No Of Docs With Response Pg | O9: =COUNTIFS(F2:F36,"<>")
A10: 20260810 HOK ClustR BV.pdf | C10: LEGAL OWNER | H10: 0.95 | K10: Highlighted rows = file(s) not in the annotation sheet; excluded from all metrics above.
A11: 20270801 - Getekende Allonge II Advario BV.pdf | C11: LEGAL OWNER | H11: 0.95 | K11: Validation Rules Example
A12: 240119 HOVK Spoorlaan 446-448 Tilburg signed.pdf | C12: LEGAL OWNER | H12: 0.95 | K12: Manual Data | L12: Response Data | M12: Result
A13: 27001 Rijksvastgoedbedrijf Huurovereenkomst - __27-01-2026_9-07-56.pdf | C13: LEGAL OWNER | H13: 0.95 | K13: 100 | L13: 100 | M13: TP
A14: CBRE_AT_Services_ENG_-_RITUALS_CBRE signed.pdf | C14: TENANT | H14: 0.95 | L14: 100 | M14: FP
A15: CBRE_Engagement_Letter_Alnylam_20260525_CLEAN_Version_signed all.pdf | C15: TENANT | H15: 0.95 | K15: 100 | L15: 200 | M15: FP
A16: COMPL DEF Huurovereenkomst - Skybox - Pepperl+Fuchs - 20260204.pdf | C16: LEGAL OWNER | H16: 0.96958763 | K16: 100 | M16: FN
A17: COMPL Huurovereenkomst - Stichting CCE - Kantoorgebouw Metzpoint I Dr. Holtroplaan - Fully Signed.pdf | C17: LEGAL OWNER | H17: 0.95 | M17: TN
A18: COMPL Regel Partners - HOVK - Luchthavenweg 81 - 20260728.pdf | C18: LEGAL OWNER | H18: 0.95
A19: COMPL_-_Onderhuurovereenkomst_Zelfstroom_B.V._-_50five_B.V._-_kantoorgebouw_Riva_-_05032026.pdf | C19: LEGAL OWNER | H19: 0.95 | K19: Field: | L19: Companies / role_desc
A20: Den Bosch, Ruwekampweg 4, HOVK getekend.pdf | C20: LEGAL OWNER | H20: 0.96476684
A21: FULLY SIGNED - COMPL Huurovereenkomst - Heijmans - Hugo de Grootlaan 23 's-Hertogenbosch V2 30-9-2025.pdf | C21: LEGAL OWNER | H21: 0.95
A22: FULLY SIGNED - DEF_COMPL_Huurovereenkomst_Robo_Charge_-_Campus_Offices_-_20260220.pdf | C22: LEGAL OWNER | H22: 0.95
A23: FULLY SIGNED - Onderhuurovereenkomst Aartshertogenlaan 223, `s-Hertogenbosch - Koning Willem I College B.V. 2606202.pdf | C23: LEGAL OWNER | H23: 0.95
A24: FULLY SIGNED COMPL_DEF_Huurovereenkomst_Bond_Bergschot_Breda.pdf | C24: LEGAL OWNER | H24: 0.95
A25: FullySigned_Allonge_II_Virtual_Vaults_Nederland.pdf | C25: LEGAL OWNER | H25: 0.95
A26: FullySigned_Lease_Agreement_Neste_EDGE_Coolsingel.pdf | C26: LEGAL OWNER | H26: 0.95
A27: HOK Waalhaven Group (signed).pdf | C27: LEGAL OWNER | H27: 0.95
A28: Hovk Avans (3e+4e+5e verd.) 20140425.pdf | C28: LEGAL OWNER | H28: 0.96958763
A29: HOVK Power4People 2025.pdf | C29: LEGAL OWNER | H29: 0.95
A30: Huurovereenkomst (Semmie Group B.V.) - Wilhelminasingel 19, Breda.pdf | C30: LEGAL OWNER | H30: 0.95
A31: Huurovereenkomst - proces-verbaal van oplevering - sleuteloverdracht - Kennedyplein 101 - getekend.pdf | C31: LEGAL OWNER | H31: 0.95
... A36: MWO CBRE SPA (ITALY) CBRE_090724.pdf | C36: LEGAL OWNER | H36: 0.96958763

Sheet Field 3
A1: Doc Name | B1: Manual Data | C1: Response Data | D1: Result | E1: Manual Pg | F1: Response Pg No | G1: Pg Result | H1: Confidence | K1: SUMMARY SHEET | N1: PAGE SUMMARY SHEET
A2: 20181204 Huurovereenkomst (GETEKEND).PDF | C2: N | H2: 0.95287958 | K2: Metrics | L2: Percentage | N2: Metrics | O2: Percentage
A3: 2024.10.30_Office Rental Agreement Labs_Gruyter Fabriek.pdf | C3: N | H3: 0.95287958 | K3: Precision | L3: =IFERROR(COUNTIFS(D2:D36,"TP")/(COUNTIFS(D2:D36,"TP")+COUNTIFS(D2:D36,"FP")),0) | N3: Precision | O3: =IFERROR(COUNTIFS(G2:G36,"TP")/(COUNTIFS(G2:G36,"TP")+COUNTIFS(G2:G36,"FP")),0)
A4: 20240606_HOK AKD - EDGE Eindhoven execution version.pdf | C4: N | H4: 0.97435897 | K4: Recall | L4: =IFERROR(COUNTIFS(D2:D36,"TP")/(COUNTIFS(D2:D36,"TP")+COUNTIFS(D2:D36,"FN")),0) | N4: Recall | O4: =IFERROR(COUNTIFS(G2:G36,"TP")/(COUNTIFS(G2:G36,"TP")+COUNTIFS(G2:G36,"FN")),0)
A5: 20250117_HOK Duke Strategies - Hambaken A.05.09 DEF FULLY SIGNED.pdf | C5: N | H5: 0.95287958 | K5: F1 Score | L5: =IFERROR(2*COUNTIFS(D2:D36,"TP")/(2*COUNTIFS(D2:D36,"TP")+COUNTIFS(D2:D36,"FP")+COUNTIFS(D2:D36,"FN")),0) | N5: F1 Score | O5: =IFERROR(2*COUNTIFS(G2:G36,"TP")/(2*COUNTIFS(G2:G36,"TP")+COUNTIFS(G2:G36,"FP")+COUNTIFS(G2:G36,"FN")),0)
A6: 20251216 Lease agreement ASPEN - signed.pdf | C6: N | H6: 0.95011601 | K6: Accuracy % (With Not Exist) | L6: =IFERROR((COUNTIF(D2:D36,"TP")+COUNTIF(D2:D36,"TN"))/SUM(COUNTIF(D2:D36,{"TP","TN","FP","FN"})),0) | N6: Accuracy % (With Not Exist) | O6: =IFERROR((COUNTIF(G2:G36,"TP")+COUNTIF(G2:G36,"TN"))/SUM(COUNTIF(G2:G36,{"TP","TN","FP","FN"})),0)
A7: 20260220 Huurovereenkomst signed 20-02-2026.pdf | C7: N | H7: 0.95011601 | K7: Total Docs Tested | L7: =COUNTA(A2:A36) | N7: Total Docs Tested | O7: =COUNTA(A2:A36)
A8: 20260629 HOK ADHDcentraal BV (1).pdf | C8: N | H8: 0.912 | K8: No Of Docs With Data | L8: =COUNTIFS(B2:B36,"<>",B2:B36,"<>N/A",B2:B36,"<>Not Present In the Document",B2:B36,"<>Not Found",B2:B36,"<>i dont know",B2:B36,"<>i don't know") | N8: No Of Docs With Manual Pg | O8: =COUNTIFS(E2:E36,"<>",E2:E36,"<>N/A",E2:E36,"<>Not Present In the Document",E2:E36,"<>Not Found",E2:E36,"<>i dont know",E2:E36,"<>i don't know")
A9: 20260807_Happy_Village_B.V._Lease_Maasstadweg_tekenversie_incl._bijlagen en-GB.pdf | C9: N | H9: 0.95287958 | K9: No Of Docs With Response | L9: =COUNTIFS(C2:C36,"<>") | N9: No Of Docs With Response Pg | O9: =COUNTIFS(F2:F36,"<>")
A10: 20260810 HOK ClustR BV.pdf | C10: N | H10: 0.95287958 | K10: Highlighted rows = file(s) not in the annotation sheet; excluded from all metrics above.
A11: 20270801 - Getekende Allonge II Advario BV.pdf | C11: N | H11: 0.95011601 | K11: Validation Rules Example
A12: 240119 HOVK Spoorlaan 446-448 Tilburg signed.pdf | C12: N | H12: 1 | K12: Manual Data | L12: Response Data | M12: Result
A13: 27001 Rijksvastgoedbedrijf Huurovereenkomst - __27-01-2026_9-07-56.pdf | C13: N | H13: 0.95287958 | K13: 100 | L13: 100 | M13: TP
A14: CBRE_AT_Services_ENG_-_RITUALS_CBRE signed.pdf | C14: N | H14: 0.95287958 | L14: 100 | M14: FP
A15: CBRE_Engagement_Letter_Alnylam_20260525_CLEAN_Version_signed all.pdf | C15: N | H15: 0.95287958 | K15: 100 | L15: 200 | M15: FP
A16: COMPL DEF Huurovereenkomst - Skybox - Pepperl+Fuchs - 20260204.pdf | C16: N | H16: 1 | K16: 100 | M16: FN
A17: COMPL Huurovereenkomst - Stichting CCE - Kantoorgebouw Metzpoint I Dr. Holtroplaan - Fully Signed.pdf | M17: TN
A18: COMPL Regel Partners - HOVK - Luchthavenweg 81 - 20260728.pdf | C18: N | H18: 0.92966361
A19: COMPL_-_Onderhuurovereenkomst_Zelfstroom_B.V._-_50five_B.V._-_kantoorgebouw_Riva_-_05032026.pdf | C19: N | H19: 0.98455902 | K19: Field: | L19: Lease_Comp_Details / act_1954_f
A20: Den Bosch, Ruwekampweg 4, HOVK getekend.pdf | C20: N | H20: 1
A21: FULLY SIGNED - COMPL Huurovereenkomst - Heijmans - Hugo de Grootlaan 23 's-Hertogenbosch V2 30-9-2025.pdf | C21: N | H21: 0.95287958
A22: FULLY SIGNED - DEF_COMPL_Huurovereenkomst_Robo_Charge_-_Campus_Offices_-_20260220.pdf | C22: N | H22: 0.95011601
A23: FULLY SIGNED - Onderhuurovereenkomst Aartshertogenlaan 223, `s-Hertogenbosch - Koning Willem I College B.V. 2606202.pdf | C23: N | H23: 0.96067416
A24: FULLY SIGNED COMPL_DEF_Huurovereenkomst_Bond_Bergschot_Breda.pdf | C24: N | H24: 1
A25: FullySigned_Allonge_II_Virtual_Vaults_Nederland.pdf | C25: Y | H25: 1
A26: FullySigned_Lease_Agreement_Neste_EDGE_Coolsingel.pdf | C26: N | H26: 0.95287958
A27: HOK Waalhaven Group (signed).pdf | C27: N | H27: 0.95287958
A28: Hovk Avans (3e+4e+5e verd.) 20140425.pdf | C28: N | H28: 0.95011601
A29: HOVK Power4People 2025.pdf | C29: N | H29: 0.95287958
A30: Huurovereenkomst (Semmie Group B.V.) - Wilhelminasingel 19, Breda.pdf | C30: N | H30: 1
A31: Huurovereenkomst - proces-verbaal van oplevering - sleuteloverdracht - Kennedyplein 101 - getekend.pdf | C31: N | H31: 0.9795376
... A36: MWO CBRE SPA (ITALY) CBRE_090724.pdf | C36: N | H36: 0.95287958

Sheet Field 4
A1: Doc Name | B1: Manual Data | C1: Response Data | D1: Result | E1: Manual Pg | F1: Response Pg No | G1: Pg Result | H1: Confidence | K1: SUMMARY SHEET | N1: PAGE SUMMARY SHEET
A2: 20181204 Huurovereenkomst (GETEKEND).PDF | C2: Contract Terms | H2: 0.98206751 | K2: Metrics | L2: Percentage | N2: Metrics | O2: Percentage
A3: 2024.10.30_Office Rental Agreement Labs_Gruyter Fabriek.pdf | C3: Contract Terms | H3: 0.42192103 | K3: Precision | L3: =IFERROR(COUNTIFS(D2:D36,"TP")/(COUNTIFS(D2:D36,"TP")+COUNTIFS(D2:D36,"FP")),0) | N3: Precision | O3: =IFERROR(COUNTIFS(G2:G36,"TP")/(COUNTIFS(G2:G36,"TP")+COUNTIFS(G2:G36,"FP")),0)
A4: 20240606_HOK AKD - EDGE Eindhoven execution version.pdf | C4: Contract Terms | H4: 0.9795376 | K4: Recall | L4: =IFERROR(COUNTIFS(D2:D36,"TP")/(COUNTIFS(D2:D36,"TP")+COUNTIFS(D2:D36,"FN")),0) | N4: Recall | O4: =IFERROR(COUNTIFS(G2:G36,"TP")/(COUNTIFS(G2:G36,"TP")+COUNTIFS(G2:G36,"FN")),0)
A5: 20250117_HOK Duke Strategies - Hambaken A.05.09 DEF FULLY SIGNED.pdf | C5: Contract Terms | H5: 0.9795376 | K5: F1 Score | L5: =IFERROR(2*COUNTIFS(D2:D36,"TP")/(2*COUNTIFS(D2:D36,"TP")+COUNTIFS(D2:D36,"FP")+COUNTIFS(D2:D36,"FN")),0) | N5: F1 Score | O5: =IFERROR(2*COUNTIFS(G2:G36,"TP")/(2*COUNTIFS(G2:G36,"TP")+COUNTIFS(G2:G36,"FP")+COUNTIFS(G2:G36,"FN")),0)
A6: 20251216 Lease agreement ASPEN - signed.pdf | C6: Contract Terms | H6: 0.9795376 | K6: Accuracy % (With Not Exist) | L6: =IFERROR((COUNTIF(D2:D36,"TP")+COUNTIF(D2:D36,"TN"))/SUM(COUNTIF(D2:D36,{"TP","TN","FP","FN"})),0) | N6: Accuracy % (With Not Exist) | O6: =IFERROR((COUNTIF(G2:G36,"TP")+COUNTIF(G2:G36,"TN"))/SUM(COUNTIF(G2:G36,{"TP","TN","FP","FN"})),0)
A7: 20260220 Huurovereenkomst signed 20-02-2026.pdf | C7: Contract Terms | H7: 0.98206751 | K7: Total Docs Tested | L7: =COUNTA(A2:A36) | N7: Total Docs Tested | O7: =COUNTA(A2:A36)
A8: 20260629 HOK ADHDcentraal BV (1).pdf | C8: Contract Terms | H8: 0.98206751 | K8: No Of Docs With Data | L8: =COUNTIFS(B2:B36,"<>",B2:B36,"<>N/A",B2:B36,"<>Not Present In the Document",B2:B36,"<>Not Found",B2:B36,"<>i dont know",B2:B36,"<>i don't know") | N8: No Of Docs With Manual Pg | O8: =COUNTIFS(E2:E36,"<>",E2:E36,"<>N/A",E2:E36,"<>Not Present In the Document",E2:E36,"<>Not Found",E2:E36,"<>i dont know",E2:E36,"<>i don't know")
A9: 20260807_Happy_Village_B.V._Lease_Maasstadweg_tekenversie_incl._bijlagen en-GB.pdf | C9: Contract Terms | H9: 0.98455902 | K9: No Of Docs With Response | L9: =COUNTIFS(C2:C36,"<>") | N9: No Of Docs With Response Pg | O9: =COUNTIFS(F2:F36,"<>")
A10: 20260810 HOK ClustR BV.pdf | C10: Contract Terms | H10: 0.98206751 | K10: Highlighted rows = file(s) not in the annotation sheet; excluded from all metrics above.
A11: 20270801 - Getekende Allonge II Advario BV.pdf | C11: Contract Terms | H11: 0.98455902 | K11: Validation Rules Example
A12: 240119 HOVK Spoorlaan 446-448 Tilburg signed.pdf | C12: Contract Terms | H12: 0.98455902 | K12: Manual Data | L12: Response Data | M12: Result
A13: 27001 Rijksvastgoedbedrijf Huurovereenkomst - __27-01-2026_9-07-56.pdf | C13: Contract Terms | H13: 0.98206751 | K13: 100 | L13: 100 | M13: TP
A14: CBRE_AT_Services_ENG_-_RITUALS_CBRE signed.pdf | C14: Contract Terms | H14: 0.9795376 | L14: 100 | M14: FP
A15: CBRE_Engagement_Letter_Alnylam_20260525_CLEAN_Version_signed all.pdf | C15: Contract Terms | H15: 0.98206751 | K15: 100 | L15: 200 | M15: FP
A16: COMPL DEF Huurovereenkomst - Skybox - Pepperl+Fuchs - 20260204.pdf | C16: Contract Terms | H16: 0.9795376 | K16: 100 | M16: FN
A17: COMPL Huurovereenkomst - Stichting CCE - Kantoorgebouw Metzpoint I Dr. Holtroplaan - Fully Signed.pdf | C17: Contract Terms | H17: 0.44646423 | M17: TN
A18: COMPL Regel Partners - HOVK - Luchthavenweg 81 - 20260728.pdf | C18: Contract Terms | H18: 0.98206751
A19: COMPL_-_Onderhuurovereenkomst_Zelfstroom_B.V._-_50five_B.V._-_kantoorgebouw_Riva_-_05032026.pdf | C19: Contract Terms | H19: 0.98455902 | K19: Field: | L19: Lease_Comp_Details / arrangement_end_action_status_reason_type_desc
A20: Den Bosch, Ruwekampweg 4, HOVK getekend.pdf | C20: Contract Terms | H20: 0.98206751
A21: FULLY SIGNED - COMPL Huurovereenkomst - Heijmans - Hugo de Grootlaan 23 's-Hertogenbosch V2 30-9-2025.pdf | C21: Contract Terms | H21: 0.98206751
A22: FULLY SIGNED - DEF_COMPL_Huurovereenkomst_Robo_Charge_-_Campus_Offices_-_20260220.pdf | C22: Contract Terms | H22: 0.98455902
A23: FULLY SIGNED - Onderhuurovereenkomst Aartshertogenlaan 223, `s-Hertogenbosch - Koning Willem I College B.V. 2606202.pdf | C23: Contract Terms | H23: 0.98455902
A24: FULLY SIGNED COMPL_DEF_Huurovereenkomst_Bond_Bergschot_Breda.pdf | C24: Contract Terms | H24: 0.9795376
A25: FullySigned_Allonge_II_Virtual_Vaults_Nederland.pdf | C25: Occupier Has Renewed/Regeared | H25: 0.98206751
A26: FullySigned_Lease_Agreement_Neste_EDGE_Coolsingel.pdf | C26: Contract Terms | H26: 0.9795376
A27: HOK Waalhaven Group (signed).pdf | C27: Contract Terms | H27: 0.98206751
A28: Hovk Avans (3e+4e+5e verd.) 20140425.pdf | C28: Contract Terms | H28: 0.97435897
A29: HOVK Power4People 2025.pdf | C29: Contract Terms | H29: 0.98206751
A30: Huurovereenkomst (Semmie Group B.V.) - Wilhelminasingel 19, Breda.pdf | C30: Contract Terms | H30: 0.98206751
A31: Huurovereenkomst - proces-verbaal van oplevering - sleuteloverdracht - Kennedyplein 101 - getekend.pdf | C31: Contract Terms | H31: 0.98206751
... A36: MWO CBRE SPA (ITALY) CBRE_090724.pdf | C36: Contract Terms | H36: 0.98206751

Sheet Field 5
A1: Doc Name | B1: Manual Data | C1: Response Data | D1: Result | E1: Manual Pg | F1: Response Pg No | G1: Pg Result | H1: Confidence | K1: SUMMARY SHEET | N1: PAGE SUMMARY SHEET
A2: 20181204 Huurovereenkomst (GETEKEND).PDF | C2: To Expire | H2: 0.35829616 | K2: Metrics | L2: Percentage | N2: Metrics | O2: Percentage
A3: 2024.10.30_Office Rental Agreement Labs_Gruyter Fabriek.pdf | C3: To Expire | H3: 0.98455902 | K3: Precision | L3: =IFERROR(COUNTIFS(D2:D36,"TP")/(COUNTIFS(D2:D36,"TP")+COUNTIFS(D2:D36,"FP")),0) | N3: Precision | O3: =IFERROR(COUNTIFS(G2:G36,"TP")/(COUNTIFS(G2:G36,"TP")+COUNTIFS(G2:G36,"FP")),0)
A4: 20240606_HOK AKD - EDGE Eindhoven execution version.pdf | C4: To Expire | H4: 0.98206751 | K4: Recall | L4: =IFERROR(COUNTIFS(D2:D36,"TP")/(COUNTIFS(D2:D36,"TP")+COUNTIFS(D2:D36,"FN")),0) | N4: Recall | O4: =IFERROR(COUNTIFS(G2:G36,"TP")/(COUNTIFS(G2:G36,"TP")+COUNTIFS(G2:G36,"FN")),0)
A5: 20250117_HOK Duke Strategies - Hambaken A.05.09 DEF FULLY SIGNED.pdf | C5: To Expire | H5: 0.35829616 | K5: F1 Score | L5: =IFERROR(2*COUNTIFS(D2:D36,"TP")/(2*COUNTIFS(D2:D36,"TP")+COUNTIFS(D2:D36,"FP")+COUNTIFS(D2:D36,"FN")),0) | N5: F1 Score | O5: =IFERROR(2*COUNTIFS(G2:G36,"TP")/(2*COUNTIFS(G2:G36,"TP")+COUNTIFS(G2:G36,"FP")+COUNTIFS(G2:G36,"FN")),0)
A6: 20251216 Lease agreement ASPEN - signed.pdf | C6: To Expire | H6: 0.98206751 | K6: Accuracy % (With Not Exist) | L6: =IFERROR((COUNTIF(D2:D36,"TP")+COUNTIF(D2:D36,"TN"))/SUM(COUNTIF(D2:D36,{"TP","TN","FP","FN"})),0) | N6: Accuracy % (With Not Exist) | O6: =IFERROR((COUNTIF(G2:G36,"TP")+COUNTIF(G2:G36,"TN"))/SUM(COUNTIF(G2:G36,{"TP","TN","FP","FN"})),0)
A7: 20260220 Huurovereenkomst signed 20-02-2026.pdf | C7: To Expire | H7: 0.35829616 | K7: Total Docs Tested | L7: =COUNTA(A2:A36) | N7: Total Docs Tested | O7: =COUNTA(A2:A36)
A8: 20260629 HOK ADHDcentraal BV (1).pdf | C8: To Expire | H8: 0.98206751 | K8: No Of Docs With Data | L8: =COUNTIFS(B2:B36,"<>",B2:B36,"<>N/A",B2:B36,"<>Not Present In the Document",B2:B36,"<>Not Found",B2:B36,"<>i dont know",B2:B36,"<>i don't know") | N8: No Of Docs With Manual Pg | O8: =COUNTIFS(E2:E36,"<>",E2:E36,"<>N/A",E2:E36,"<>Not Present In the Document",E2:E36,"<>Not Found",E2:E36,"<>i dont know",E2:E36,"<>i don't know")
A9: 20260807_Happy_Village_B.V._Lease_Maasstadweg_tekenversie_incl._bijlagen en-GB.pdf | C9: To Expire | H9: 0.9795376 | K9: No Of Docs With Response | L9: =COUNTIFS(C2:C36,"<>") | N9: No Of Docs With Response Pg | O9: =COUNTIFS(F2:F36,"<>")
A10: 20260810 HOK ClustR BV.pdf | C10: To Expire | H10: 0.35829616 | K10: Highlighted rows = file(s) not in the annotation sheet; excluded from all metrics above.
A11: 20270801 - Getekende Allonge II Advario BV.pdf | C11: To Expire | H11: 0.9795376 | K11: Validation Rules Example
A12: 240119 HOVK Spoorlaan 446-448 Tilburg signed.pdf | C12: To Expire | H12: 0.35829616 | K12: Manual Data | L12: Response Data | M12: Result
A13: 27001 Rijksvastgoedbedrijf Huurovereenkomst - __27-01-2026_9-07-56.pdf | C13: To Expire | H13: 0.98206751 | K13: 100 | L13: 100 | M13: TP
A14: CBRE_AT_Services_ENG_-_RITUALS_CBRE signed.pdf | C14: To Expire | H14: 0.97435897 | L14: 100 | M14: FP
A15: CBRE_Engagement_Letter_Alnylam_20260525_CLEAN_Version_signed all.pdf | C15: To Expire | H15: 0.35795886 | K15: 100 | L15: 200 | M15: FP
A16: COMPL DEF Huurovereenkomst - Skybox - Pepperl+Fuchs - 20260204.pdf | C16: To Expire | H16: 0.9795376 | K16: 100 | M16: FN
A17: COMPL Huurovereenkomst - Stichting CCE - Kantoorgebouw Metzpoint I Dr. Holtroplaan - Fully Signed.pdf | C17: To Expire | H17: 0.9795376 | M17: TN
A18: COMPL Regel Partners - HOVK - Luchthavenweg 81 - 20260728.pdf | C18: To Expire | H18: 0.98206751
A19: COMPL_-_Onderhuurovereenkomst_Zelfstroom_B.V._-_50five_B.V._-_kantoorgebouw_Riva_-_05032026.pdf | C19: To Expire | H19: 0.98206751 | K19: Field: | L19: Lease_Comp_Details / arrangement_end_action_status_type_desc
A20: Den Bosch, Ruwekampweg 4, HOVK getekend.pdf | C20: To Expire | H20: 0.35726496
A21: FULLY SIGNED - COMPL Huurovereenkomst - Heijmans - Hugo de Grootlaan 23 's-Hertogenbosch V2 30-9-2025.pdf | C21: To Expire | H21: 0.9769684
A22: FULLY SIGNED - DEF_COMPL_Huurovereenkomst_Robo_Charge_-_Campus_Offices_-_20260220.pdf | C22: To Expire | H22: 0.35829616
A23: FULLY SIGNED - Onderhuurovereenkomst Aartshertogenlaan 223, `s-Hertogenbosch - Koning Willem I College B.V. 2606202.pdf | C23: To Expire | H23: 0.98455902
A24: FULLY SIGNED COMPL_DEF_Huurovereenkomst_Bond_Bergschot_Breda.pdf | C24: To Expire | H24: 0.35795886
A25: FullySigned_Allonge_II_Virtual_Vaults_Nederland.pdf | C25: To Expire | H25: 0.44542879
A26: FullySigned_Lease_Agreement_Neste_EDGE_Coolsingel.pdf | C26: To Expire | H26: 0.35795886
A27: HOK Waalhaven Group (signed).pdf | C27: To Expire | H27: 0.9795376
A28: Hovk Avans (3e+4e+5e verd.) 20140425.pdf | C28: To Expire | H28: 0.35829616
A29: HOVK Power4People 2025.pdf | C29: To Expire | H29: 0.9795376
A30: Huurovereenkomst (Semmie Group B.V.) - Wilhelminasingel 19, Breda.pdf | C30: To Expire | H30: 0.35829616
A31: Huurovereenkomst - proces-verbaal van oplevering - sleuteloverdracht - Kennedyplein 101 - getekend.pdf | C31: To Expire | H31: 0.98206751
... A36: MWO CBRE SPA (ITALY) CBRE_090724.pdf | C36: To Expire | H36: 0.9795376

Sheet Field 6
A1: Doc Name | B1: Manual Data | C1: Response Data | D1: Result | E1: Manual Pg | F1: Response Pg No | G1: Pg Result | H1: Confidence | K1: SUMMARY SHEET | N1: PAGE SUMMARY SHEET
A2: 20181204 Huurovereenkomst (GETEKEND).PDF | C2: 12/31/33 | H2: 0.98206751 | K2: Metrics | L2: Percentage | N2: Metrics | O2: Percentage
A3: 2024.10.30_Office Rental Agreement Labs_Gruyter Fabriek.pdf | C3: 12/31/29 | H3: 0.98206751 | K3: Precision | L3: =IFERROR(COUNTIFS(D2:D36,"TP")/(COUNTIFS(D2:D36,"TP")+COUNTIFS(D2:D36,"FP")),0) | N3: Precision | O3: =IFERROR(COUNTIFS(G2:G36,"TP")/(COUNTIFS(G2:G36,"TP")+COUNTIFS(G2:G36,"FP")),0)
A4: 20240606_HOK AKD - EDGE Eindhoven execution version.pdf | C4: 06/30/36 | H4: 0.92898348 | K4: Recall | L4: =IFERROR(COUNTIFS(D2:D36,"TP")/(COUNTIFS(D2:D36,"TP")+COUNTIFS(D2:D36,"FN")),0) | N4: Recall | O4: =IFERROR(COUNTIFS(G2:G36,"TP")/(COUNTIFS(G2:G36,"TP")+COUNTIFS(G2:G36,"FN")),0)
A5: 20250117_HOK Duke Strategies - Hambaken A.05.09 DEF FULLY SIGNED.pdf | C5: 02/16/26 | H5: 0.9795376 | K5: F1 Score | L5: =IFERROR(2*COUNTIFS(D2:D36,"TP")/(2*COUNTIFS(D2:D36,"TP")+COUNTIFS(D2:D36,"FP")+COUNTIFS(D2:D36,"FN")),0) | N5: F1 Score | O5: =IFERROR(2*COUNTIFS(G2:G36,"TP")/(2*COUNTIFS(G2:G36,"TP")+COUNTIFS(G2:G36,"FP")+COUNTIFS(G2:G36,"FN")),0)
A6: 20251216 Lease agreement ASPEN - signed.pdf | C6: 10/31/37 | H6: 0.93475936 | K6: Accuracy % (With Not Exist) | L6: =IFERROR((COUNTIF(D2:D36,"TP")+COUNTIF(D2:D36,"TN"))/SUM(COUNTIF(D2:D36,{"TP","TN","FP","FN"})),0) | N6: Accuracy % (With Not Exist) | O6: =IFERROR((COUNTIF(G2:G36,"TP")+COUNTIF(G2:G36,"TN"))/SUM(COUNTIF(G2:G36,{"TP","TN","FP","FN"})),0)
A7: 20260220 Huurovereenkomst signed 20-02-2026.pdf | C7: 03/01/28 | H7: 0.98206751 | K7: Total Docs Tested | L7: =COUNTA(A2:A36) | N7: Total Docs Tested | O7: =COUNTA(A2:A36)
A8: 20260629 HOK ADHDcentraal BV (1).pdf | C8: 08/31/30 | H8: 0.85993161 | K8: No Of Docs With Data | L8: =COUNTIFS(B2:B36,"<>",B2:B36,"<>N/A",B2:B36,"<>Not Present In the Document",B2:B36,"<>Not Found",B2:B36,"<>i dont know",B2:B36,"<>i don't know") | N8: No Of Docs With Manual Pg | O8: =COUNTIFS(E2:E36,"<>",E2:E36,"<>N/A",E2:E36,"<>Not Present In the Document",E2:E36,"<>Not Found",E2:E36,"<>i dont know",E2:E36,"<>i don't know")
A9: 20260807_Happy_Village_B.V._Lease_Maasstadweg_tekenversie_incl._bijlagen en-GB.pdf | C9: 01/01/34 | H9: 0.9795376 | K9: No Of Docs With Response | L9: =COUNTIFS(C2:C36,"<>") | N9: No Of Docs With Response Pg | O9: =COUNTIFS(F2:F36,"<>")
A10: 20260810 HOK ClustR BV.pdf | C10: 09/30/28 | H10: 0.83572523 | K10: Highlighted rows = file(s) not in the annotation sheet; excluded from all metrics above.
A11: 20270801 - Getekende Allonge II Advario BV.pdf | C11: 07/31/30 | H11: 0.9235264 | K11: Validation Rules Example
A12: 240119 HOVK Spoorlaan 446-448 Tilburg signed.pdf | C12: 03/31/27 | H12: 0.9795376 | K12: Manual Data | L12: Response Data | M12: Result
A13: 27001 Rijksvastgoedbedrijf Huurovereenkomst - __27-01-2026_9-07-56.pdf | C13: 12/31/27 | H13: 0.95 | K13: 100 | L13: 100 | M13: TP
A14: CBRE_AT_Services_ENG_-_RITUALS_CBRE signed.pdf | L14: 100 | M14: FP
A15: CBRE_Engagement_Letter_Alnylam_20260525_CLEAN_Version_signed all.pdf | C15: 03/06/26 | H15: 0.80545373 | K15: 100 | L15: 200 | M15: FP
A16: COMPL DEF Huurovereenkomst - Skybox - Pepperl+Fuchs - 20260204.pdf | C16: 11/30/31 | H16: 0.98206751 | K16: 100 | M16: FN
A17: COMPL Huurovereenkomst - Stichting CCE - Kantoorgebouw Metzpoint I Dr. Holtroplaan - Fully Signed.pdf | C17: 04/30/35 | H17: 0.96067416 | M17: TN
A18: COMPL Regel Partners - HOVK - Luchthavenweg 81 - 20260728.pdf | C18: 09/30/31 | H18: 0.76224699
A19: COMPL_-_Onderhuurovereenkomst_Zelfstroom_B.V._-_50five_B.V._-_kantoorgebouw_Riva_-_05032026.pdf | C19: 06/01/26 | H19: 0.98206751 | K19: Field: | L19: Lease_Comp_Details / arrangement_end_future_action_date
A20: Den Bosch, Ruwekampweg 4, HOVK getekend.pdf | C20: 12/31/21 | H20: 0.9235264
A21: FULLY SIGNED - COMPL Huurovereenkomst - Heijmans - Hugo de Grootlaan 23 's-Hertogenbosch V2 30-9-2025.pdf | C21: 09/30/26 | H21: 0.83195266
A22: FULLY SIGNED - DEF_COMPL_Huurovereenkomst_Robo_Charge_-_Campus_Offices_-_20260220.pdf | C22: 03/31/31 | H22: 0.81302871
A23: FULLY SIGNED - Onderhuurovereenkomst Aartshertogenlaan 223, `s-Hertogenbosch - Koning Willem I College B.V. 2606202.pdf | C23: 11/01/28 | H23: 0.73986755
A24: FULLY SIGNED COMPL_DEF_Huurovereenkomst_Bond_Bergschot_Breda.pdf | C24: 12/31/28 | H24: 0.98206751
A25: FullySigned_Allonge_II_Virtual_Vaults_Nederland.pdf | C25: 10/31/27 | H25: 0.97435897
A26: FullySigned_Lease_Agreement_Neste_EDGE_Coolsingel.pdf | C26: 07/31/37 | H26: 0.9235264
A27: HOK Waalhaven Group (signed).pdf | C27: 08/31/31 | H27: 0.65864874
A28: Hovk Avans (3e+4e+5e verd.) 20140425.pdf | C28: 06/30/19 | H28: 0.83572523
A29: HOVK Power4People 2025.pdf | C29: 06/30/26 | H29: 0.87268423
A30: Huurovereenkomst (Semmie Group B.V.) - Wilhelminasingel 19, Breda.pdf | C30: 04/30/29 | H30: 0.80784562
A31: Huurovereenkomst - proces-verbaal van oplevering - sleuteloverdracht - Kennedyplein 101 - getekend.pdf | C31: 02/28/29 | H31: 0.9795376
... A36: MWO CBRE SPA (ITALY) CBRE_090724.pdf | C36: 09/24/24 | H36: 0.90497238

Sheet Field 7
A1: Doc Name | B1: Manual Data | C1: Response Data | D1: Result | E1: Manual Pg | F1: Response Pg No | G1: Pg Result | H1: Confidence | K1: SUMMARY SHEET | N1: PAGE SUMMARY SHEET
A2: 20181204 Huurovereenkomst (GETEKEND).PDF | C2: To Be Revisited | H2: 0.96901563 | K2: Metrics | L2: Percentage | N2: Metrics | O2: Percentage
A3: 2024.10.30_Office Rental Agreement Labs_Gruyter Fabriek.pdf | C3: To Be Revisited | H3: 0.98455902 | K3: Precision | L3: =IFERROR(COUNTIFS(D2:D36,"TP")/(COUNTIFS(D2:D36,"TP")+COUNTIFS(D2:D36,"FP")),0) | N3: Precision | O3: =IFERROR(COUNTIFS(G2:G36,"TP")/(COUNTIFS(G2:G36,"TP")+COUNTIFS(G2:G36,"FP")),0)
A4: 20240606_HOK AKD - EDGE Eindhoven execution version.pdf | C4: To Be Revisited | H4: 0.9795376 | K4: Recall | L4: =IFERROR(COUNTIFS(D2:D36,"TP")/(COUNTIFS(D2:D36,"TP")+COUNTIFS(D2:D36,"FN")),0) | N4: Recall | O4: =IFERROR(COUNTIFS(G2:G36,"TP")/(COUNTIFS(G2:G36,"TP")+COUNTIFS(G2:G36,"FN")),0)
A5: 20250117_HOK Duke Strategies - Hambaken A.05.09 DEF FULLY SIGNED.pdf | C5: To Be Revisited | H5: 0.97435897 | K5: F1 Score | L5: =IFERROR(2*COUNTIFS(D2:D36,"TP")/(2*COUNTIFS(D2:D36,"TP")+COUNTIFS(D2:D36,"FP")+COUNTIFS(D2:D36,"FN")),0) | N5: F1 Score | O5: =IFERROR(2*COUNTIFS(G2:G36,"TP")/(2*COUNTIFS(G2:G36,"TP")+COUNTIFS(G2:G36,"FP")+COUNTIFS(G2:G36,"FN")),0)
A6: 20251216 Lease agreement ASPEN - signed.pdf | C6: To Be Revisited | H6: 0.98206751 | K6: Accuracy % (With Not Exist) | L6: =IFERROR((COUNTIF(D2:D36,"TP")+COUNTIF(D2:D36,"TN"))/SUM(COUNTIF(D2:D36,{"TP","TN","FP","FN"})),0) | N6: Accuracy % (With Not Exist) | O6: =IFERROR((COUNTIF(G2:G36,"TP")+COUNTIF(G2:G36,"TN"))/SUM(COUNTIF(G2:G36,{"TP","TN","FP","FN"})),0)
A7: 20260220 Huurovereenkomst signed 20-02-2026.pdf | C7: New Break Date | H7: 0.9795376 | K7: Total Docs Tested | L7: =COUNTA(A2:A36) | N7: Total Docs Tested | O7: =COUNTA(A2:A36)
A8: 20260629 HOK ADHDcentraal BV (1).pdf | C8: To Be Revisited | H8: 0.95287958 | K8: No Of Docs With Data | L8: =COUNTIFS(B2:B36,"<>",B2:B36,"<>N/A",B2:B36,"<>Not Present In the Document",B2:B36,"<>Not Found",B2:B36,"<>i dont know",B2:B36,"<>i don't know") | N8: No Of Docs With Manual Pg | O8: =COUNTIFS(E2:E36,"<>",E2:E36,"<>N/A",E2:E36,"<>Not Present In the Document",E2:E36,"<>Not Found",E2:E36,"<>i dont know",E2:E36,"<>i don't know")
A9: 20260807_Happy_Village_B.V._Lease_Maasstadweg_tekenversie_incl._bijlagen en-GB.pdf | C9: New Break Date | H9: 0.98455902 | K9: No Of Docs With Response | L9: =COUNTIFS(C2:C36,"<>") | N9: No Of Docs With Response Pg | O9: =COUNTIFS(F2:F36,"<>")
A10: 20260810 HOK ClustR BV.pdf | C10: To Be Revisited | H10: 0.98455902 | K10: Highlighted rows = file(s) not in the annotation sheet; excluded from all metrics above.
A11: 20270801 - Getekende Allonge II Advario BV.pdf | C11: To Be Revisited | H11: 0.59202899 | K11: Validation Rules Example
A12: 240119 HOVK Spoorlaan 446-448 Tilburg signed.pdf | C12: To Be Revisited | H12: 0.59202899 | K12: Manual Data | L12: Response Data | M12: Result
A13: 27001 Rijksvastgoedbedrijf Huurovereenkomst - __27-01-2026_9-07-56.pdf | C13: To Be Revisited | H13: 0.9795376 | K13: 100 | L13: 100 | M13: TP
A14: CBRE_AT_Services_ENG_-_RITUALS_CBRE signed.pdf | C14: To Be Revisited | H14: 0.97435897 | L14: 100 | M14: FP
A15: CBRE_Engagement_Letter_Alnylam_20260525_CLEAN_Version_signed all.pdf | C15: To Be Revisited | H15: 0.49178439 | K15: 100 | L15: 200 | M15: FP
A16: COMPL DEF Huurovereenkomst - Skybox - Pepperl+Fuchs - 20260204.pdf | C16: To Be Revisited | H16: 0.9795376 | K16: 100 | M16: FN
A17: COMPL Huurovereenkomst - Stichting CCE - Kantoorgebouw Metzpoint I Dr. Holtroplaan - Fully Signed.pdf | C17: To Be Revisited | H17: 0.98206751 | M17: TN
A18: COMPL Regel Partners - HOVK - Luchthavenweg 81 - 20260728.pdf | C18: To Be Revisited | H18: 0.9795376
A19: COMPL_-_Onderhuurovereenkomst_Zelfstroom_B.V._-_50five_B.V._-_kantoorgebouw_Riva_-_05032026.pdf | C19: To Be Revisited | H19: 0.98206751 | K19: Field: | L19: Lease_Comp_Details / arrangement_end_future_action_type_desc
A20: Den Bosch, Ruwekampweg 4, HOVK getekend.pdf | C20: New Break Date | H20: 0.98206751
A21: FULLY SIGNED - COMPL Huurovereenkomst - Heijmans - Hugo de Grootlaan 23 's-Hertogenbosch V2 30-9-2025.pdf | C21: To Be Revisited | H21: 0.9795376
A22: FULLY SIGNED - DEF_COMPL_Huurovereenkomst_Robo_Charge_-_Campus_Offices_-_20260220.pdf | C22: To Be Revisited | H22: 0.59486608
A23: FULLY SIGNED - Onderhuurovereenkomst Aartshertogenlaan 223, `s-Hertogenbosch - Koning Willem I College B.V. 2606202.pdf | C23: To Be Revisited | H23: 0.96627971
A24: FULLY SIGNED COMPL_DEF_Huurovereenkomst_Bond_Bergschot_Breda.pdf | C24: To Be Revisited | H24: 0.98206751
A25: FullySigned_Allonge_II_Virtual_Vaults_Nederland.pdf | C25: To Be Revisited | H25: 0.9795376
A26: FullySigned_Lease_Agreement_Neste_EDGE_Coolsingel.pdf | C26: To Be Revisited | H26: 0.49240838
A27: HOK Waalhaven Group (signed).pdf | C27: To Be Revisited | H27: 0.9795376
A28: Hovk Avans (3e+4e+5e verd.) 20140425.pdf | C28: To Be Revisited | H28: 0.59202899
A29: HOVK Power4People 2025.pdf | C29: To Be Revisited | H29: 0.98206751
A30: Huurovereenkomst (Semmie Group B.V.) - Wilhelminasingel 19, Breda.pdf | C30: To Be Revisited | H30: 0.98206751
A31: Huurovereenkomst - proces-verbaal van oplevering - sleuteloverdracht - Kennedyplein 101 - getekend.pdf | C31: To Be Revisited | H31: 0.9795376
... A36: MWO CBRE SPA (ITALY) CBRE_090724.pdf | C36: To Be Revisited | H36: 0.9795376

Sheet Field 8
A1: Doc Name | B1: Manual Data | C1: Response Data | D1: Result | E1: Manual Pg | F1: Response Pg No | G1: Pg Result | H1: Confidence | K1: SUMMARY SHEET | N1: PAGE SUMMARY SHEET
A2: 20181204 Huurovereenkomst (GETEKEND).PDF | C2: New Establishment | H2: 0.51365517 | K2: Metrics | L2: Percentage | N2: Metrics | O2: Percentage
A3: 2024.10.30_Office Rental Agreement Labs_Gruyter Fabriek.pdf | C3: New Establishment | H3: 0.24370013 | K3: Precision | L3: =IFERROR(COUNTIFS(D2:D36,"TP")/(COUNTIFS(D2:D36,"TP")+COUNTIFS(D2:D36,"FP")),0) | N3: Precision | O3: =IFERROR(COUNTIFS(G2:G36,"TP")/(COUNTIFS(G2:G36,"TP")+COUNTIFS(G2:G36,"FP")),0)
A4: 20240606_HOK AKD - EDGE Eindhoven execution version.pdf | C4: Business Continuity | H4: 0.56552771 | K4: Recall | L4: =IFERROR(COUNTIFS(D2:D36,"TP")/(COUNTIFS(D2:D36,"TP")+COUNTIFS(D2:D36,"FN")),0) | N4: Recall | O4: =IFERROR(COUNTIFS(G2:G36,"TP")/(COUNTIFS(G2:G36,"TP")+COUNTIFS(G2:G36,"FN")),0)
A5: 20250117_HOK Duke Strategies - Hambaken A.05.09 DEF FULLY SIGNED.pdf | C5: New Establishment | H5: 0.50774125 | K5: F1 Score | L5: =IFERROR(2*COUNTIFS(D2:D36,"TP")/(2*COUNTIFS(D2:D36,"TP")+COUNTIFS(D2:D36,"FP")+COUNTIFS(D2:D36,"FN")),0) | N5: F1 Score | O5: =IFERROR(2*COUNTIFS(G2:G36,"TP")/(2*COUNTIFS(G2:G36,"TP")+COUNTIFS(G2:G36,"FP")+COUNTIFS(G2:G36,"FN")),0)
A6: 20251216 Lease agreement ASPEN - signed.pdf | C6: Relocation | H6: 0.98206751 | K6: Accuracy % (With Not Exist) | L6: =IFERROR((COUNTIF(D2:D36,"TP")+COUNTIF(D2:D36,"TN"))/SUM(COUNTIF(D2:D36,{"TP","TN","FP","FN"})),0) | N6: Accuracy % (With Not Exist) | O6: =IFERROR((COUNTIF(G2:G36,"TP")+COUNTIF(G2:G36,"TN"))/SUM(COUNTIF(G2:G36,{"TP","TN","FP","FN"})),0)
A7: 20260220 Huurovereenkomst signed 20-02-2026.pdf | C7: New Establishment | H7: 0.96349958 | K7: Total Docs Tested | L7: =COUNTA(A2:A36) | N7: Total Docs Tested | O7: =COUNTA(A2:A36)
A8: 20260629 HOK ADHDcentraal BV (1).pdf | C8: Business Continuity | H8: 0.44435484 | K8: No Of Docs With Data | L8: =COUNTIFS(B2:B36,"<>",B2:B36,"<>N/A",B2:B36,"<>Not Present In the Document",B2:B36,"<>Not Found",B2:B36,"<>i dont know",B2:B36,"<>i don't know") | N8: No Of Docs With Manual Pg | O8: =COUNTIFS(E2:E36,"<>",E2:E36,"<>N/A",E2:E36,"<>Not Present In the Document",E2:E36,"<>Not Found",E2:E36,"<>i dont know",E2:E36,"<>i don't know")
A9: 20260807_Happy_Village_B.V._Lease_Maasstadweg_tekenversie_incl._bijlagen en-GB.pdf | C9: Unknown | H9: 0.24266667 | K9: No Of Docs With Response | L9: =COUNTIFS(C2:C36,"<>") | N9: No Of Docs With Response Pg | O9: =COUNTIFS(F2:F36,"<>")
A10: 20260810 HOK ClustR BV.pdf | C10: New Establishment | H10: 0.9769684 | K10: Highlighted rows = file(s) not in the annotation sheet; excluded from all metrics above.
A11: 20270801 - Getekende Allonge II Advario BV.pdf | C11: Business Continuity | H11: 0.9795376 | K11: Validation Rules Example
A12: 240119 HOVK Spoorlaan 446-448 Tilburg signed.pdf | C12: New Establishment | H12: 0.24352672 | K12: Manual Data | L12: Response Data | M12: Result
A13: 27001 Rijksvastgoedbedrijf Huurovereenkomst - __27-01-2026_9-07-56.pdf | C13: Business Continuity | H13: 0.98455902 | K13: 100 | L13: 100 | M13: TP
